Workbook
Name index: 'Hypothèses'!$B$11
Name apport: 'Hypothèses'!$B$14
Name durée: 'Hypothèses'!$B$18

Sheet Hypothèses
A1: HYPOTHÈSES D'INVESTISSEMENT — Dispositif Jeanbrun
A2: ✏ SAISIE CONSEILLER — cellule modifiable | E2: 🔒 CALCULÉ AUTOMATIQUEMENT — cellule verrouillée
A3: 🏠 BIEN IMMOBILIER
A4: Prix d'acquisition | B4: 260000 | C4: € | E4: 📐 SURFACE PONDÉRÉE (Annexes)
A5: Frais d'acquisition ("frais de notaire") | B5: 0.03 | C5: % | E5: RDC (OUI / NON) | F5: NON
A6: Coût total acquisition (frais inclus) | B6: =B4*(1+B5) -> 267800 | C6: € | E6: Surface terrasse (m²) | F6: 0
E7: Surface balcon (m²) | F7: 15
A8: Surface habitable | B8: 40 | C8: m²
A9: Zone d'acquisition | B9: A | E9: Surface pondérée (m²) | F9: =B8+MIN(N(F7)+IF(F5="OUI",0,MIN(N(F6),9)),16)/2 -> 47.5
E10: Coefficient multiplicateur | F10: =TRUNC(MIN(0.7+19/F9,1.2),2) -> 1.1
A11: Indexation revenus du client et valeur du bien | B11: 0 | C11: %/an | E11: ▸ RDC=OUI → terrasse exclue ; cap 9/16 m²
E12: Loyer MAX légal (€/mois) | F12: =B24*F9*F10 -> 757.1025
A13: 💳 FINANCEMENT
A14: Apport personnel | B14: 15000 | C14: €
A15: Montant emprunté | B15: =B6-B14 -> 252800 | C15: €
A16: Taux d'intérêt annuel | B16: 0.033 | C16: %
A17: Taux assurance emprunteur | B17: 0.0035 | C17: %
A18: Durée du financement | B18: 25 | C18: ans
A19: Assurance mensuelle | B19: ='Tableau dAMT financier'!F16/12 -> 73.733333 | C19: €/mois
A20: Mensualité crédit (hors assurance) | B20: =('Tableau dAMT financier'!D16+'Tableau dAMT financier'!E16)/12 -> 1238.6228 | C20: €/mois
A21: Frais garantie + dossier + courtage | B21: 4000 | C21: €
A22: 🏘 REVENUS LOCATIFS | E22: 📋 PLAFONDS AMORTISSEMENT
A23: Type de loyer | B23: Loyer intermédiaire | E23: Loyer intermédiaire | F23: 8000
A24: Plafond loyer légal (€/m²/mois) | B24: =VLOOKUP(B9,'Plafonds loyers'!A:D,IF(B23="Loyer intermédiaire",2,IF(B23="Loyer social",3,4)),FALSE()) -> 14.49 | C24: €/m² | E24: Loyer social | F24: 10000
A25: Loyer mensuel retenu ⚠ ≤ MAX légal | B25: =MIN(F26,F12) -> 750 | C25: ≤ MAX légal | E25: Loyer très social | F25: 12000
A26: Loyer annuel | B26: =B25*12 -> 9000 | C26: €/an | E26: Loyer souhaité (conseiller) | F26: 750
A27: Indexation loyers (%/an) | B27: 0.015
A28: Charges exploit. + taxe foncière | B28: 0.3 | C28: % loyers
A30: 📊 DISPOSITIF JEANBRUN
A31: Base amortissement (80% coût total) | B31: =B4*0.8 -> 208000 | C31: €
A32: Taux d'amortissement (selon type) | B32: =IF(B23="Loyer intermédiaire",0.035,IF(B23="Loyer social",0.045,0.055)) -> 0.035 | C32: %
A33: Plafond annuel (taux × base) | B33: =VLOOKUP(B23,E23:F26,2,FALSE()) -> 8000 | C33: €/an
A34: Amortissement annuel | B34: =MIN(B33,B31*B32) -> 7280 | C34: €/an
A35: 👤 SITUATION FISCALE DU CLIENT
A36: Type de revenus | B36: Salaires (abatt. 10%)
A37: Revenus annuels déclarés | B37: 95000 | C37: €/an
A38: Revenus fonciers — autres biens | B38: 5000 | C38: €/an
A39: Nombre de parts fiscales | B39: 2.5 | C39: parts
A40: Taux prélèvements sociaux | B40: 0.172 | C40: %
A41: Nombre de déclarants | B41: 2 | C41: pers.
...

Sheet Synthèse Visuelle
B2: médicis IMMOBILIER NEUF | I2: ▸ DISPOSITIF JEANBRUN — Projection simplifiée · Simulation personnalisée
B4: REVENUS DÉCLARÉS | E4: TRANCHE MARGINALE | H4: PRIX D'ACQUISITION | K4: LOYER INITIAL | N4: SURFACE / ZONE | Q4: ÉCONOMIE FISCALE AN 1
B5: ='Hypothèses'!B37 -> 95000 | E5: ='Synthèse client - simplifiée'!C6 -> 0.3 | H5: ='Hypothèses'!B4 -> 260000 | K5: ='Hypothèses'!B25 -> 750 | N5: ='Hypothèses'!F9&" m² · Zone "&'Hypothèses'!B9 -> 47,5 m² · Zone A | Q5: ='Synthèse client - simplifiée'!E6 -> 5092.2977
B7: ='Hypothèses'!B39&" parts fiscales" -> 2,5 parts fiscales | H7: ='Hypothèses'!B23 -> Loyer intermédiaire
B9: COMPTE EN T · Moyennes mensuelles calculées sur chaque horizon
B11: 9 | C11: ans | H11: 15 | I11: ans | N11: 25 | O11: ans
B12: Fin durée d'engagement | H12: ★ Horizon de référence | N12: Financement soldé · Pleine propriété
B13: ✚ CE QUI RENTRE | E13: − CE QUI SORT | H13: ✚ CE QUI RENTRE | K13: − CE QUI SORT | N13: ✚ CE QUI RENTRE | Q13: − CE QUI SORT
B14: Loyers moy. | C14: ='Synthèse client - simplifiée'!D14 -> 796.61097 | E14: Crédit | F14: ='Synthèse client - simplifiée'!I14 -> 1312.3562 | H14: Loyers moy. | I14: ='Synthèse client - simplifiée'!D22 -> 834.10689 | K14: Crédit | L14: ='Synthèse client - simplifiée'!I22 -> 1312.3562 | N14: Loyers moy. | O14: ='Synthèse client - simplifiée'!D30 -> 901.89071 | Q14: Crédit | R14: ='Synthèse client - simplifiée'!I30 -> 1312.3562
B15: Gain fiscal | C15: ='Synthèse client - simplifiée'!D15 -> 294.11968 | E15: Charges | F15: ='Synthèse client - simplifiée'!I15 -> 238.98329 | H15: Gain fiscal | I15: ='Synthèse client - simplifiée'!D23 -> 260.14178 | K15: Charges | L15: ='Synthèse client - simplifiée'!I23 -> 250.23207 | N15: Gain fiscal | O15: ='Synthèse client - simplifiée'!D31 -> 185.12192 | Q15: Charges | R15: ='Synthèse client - simplifiée'!I31 -> 270.56721
B16: Total | C16: ='Synthèse client - simplifiée'!D16 -> 1090.7307 | E16: Total | F16: ='Synthèse client - simplifiée'!I16 -> 1551.3395 | H16: Total | I16: ='Synthèse client - simplifiée'!D24 -> 1094.2487 | K16: Total | L16: ='Synthèse client - simplifiée'!I24 -> 1562.5882 | N16: Total | O16: ='Synthèse client - simplifiée'!D32 -> 1087.0126 | Q16: Total | R16: ='Synthèse client - simplifiée'!I32 -> 1582.9234
B18: Effort d'épargne mensuel moyen | E18: =ABS('Synthèse client - simplifiée'!G17) -> 460.60881 | H18: Effort d'épargne mensuel moyen | K18: =ABS('Synthèse client - simplifiée'!G25) -> 468.33957 | N18: Effort d'épargne mensuel moyen | Q18: =ABS('Synthèse client - simplifiée'!G33) -> 495.91076
B19: ← Reste à charge mensuel réel après loyers et économie fiscale | H19: ← Reste à charge mensuel réel après loyers et économie fiscale | N19: ← Reste à charge mensuel réel après loyers et économie fiscale
B20: ="Capital net si prix de vente = prix d'achat · dont "&TEXT(ABS('Synthèse client - simplifiée'!M17),"#,##0")&" € via Jeanbrun" -> Capital net si prix de vente = prix d'achat · dont 24 236 € via Jeanbrun | H20: ="Capital net si prix de vente = prix d'achat · dont "&TEXT(ABS('Synthèse client - simplifiée'!M25),"#,##0")&" € via Jeanbrun" -> Capital net si prix de vente = prix d'achat · dont 43 189 € via Jeanbrun | N20: ="Capital net si prix de vente = prix d'achat · dont "&TEXT(ABS('Synthèse client - simplifiée'!M33),"#,##0")&" € via Jeanbrun" -> Capital net si prix de vente = prix d'achat · dont 76 066 € via Jeanbrun
B21: ='Synthèse client - simplifiée'!M14 -> 73286.154 | H21: ='Synthèse client - simplifiée'!M22 -> 122412.87 | N21: ='Synthèse client - simplifiée'!M30 -> 250441.1
B23: Capital net constitué par année de détention (Valeur revente - CRD - impôt PV) · Hypothèses de revalorisation du bien à 0% et 1,5%
B39: 💶 | C39: Le côté vert (+) | H39: 🏦 | I39: Le côté rouge (−) | N39: 📊 | O39: Le gain fiscal — 2 composantes
C40: Ce que vous percevez : loyers encaissés + économie d'impôt grâce au dispositif Jeanbrun. | I40: Ce que vous déboursez : mensualité de crédit + charges d'exploitation annuelles (gestion / GLI / taxe foncière / assurance PNO / provisions menus travaux :;ces charges sont estimées)) | O40: Déficit naturel (acquis sans Jeanbrun) + avantage lié à l'amortissement Jeanbrun. Les deux s'additionnent.
B45: www.medicis-immobilier-neuf.fr · Simulation personnalisée non contractuelle · Hypothèses d'indexation et fiscalité constantes - Tout investissementlocatif comporte des risques (location / impayés / travbaux / baisse de valeur)

Sheet Synthèse client - simplifiée
A1: PROJECTION SIMPLIFIÉE — DISPOSITIF JEANBRUN
A2: Compte en T • Moyennes mensuelles • Document non contractuel
A4: SITUATION DU FOYER | F4: OPÉRATION IMMOBILIÈRE
A5: Revenus déclarés | C5: ='Synthèse Client - détaillée'!C5 -> 95000 | D5: Parts | E5: ='Synthèse Client - détaillée'!F5 -> 2.5 | F5: Prix d'acquisition | H5: ='Synthèse Client - détaillée'!J5 -> 260000 | I5: ='Synthèse Client - détaillée'!M5 -> A
A6: TMI | C6: ='Synthèse Client - détaillée'!F6 -> 0.3 | D6: Éco. fiscale an 1 | E6: ='Synthèse Client - détaillée'!F7 -> 5092.2977 | F6: Surface pondérée | H6: ='Synthèse Client - détaillée'!J6 -> 47.5 | I6: ='Synthèse Client - détaillée'!M7
A7: Mensualité crédit | C7: ='Synthèse Client - détaillée'!F12 -> 1312.3562 | D7: Apport | E7: ='Synthèse Client - détaillée'!C10 -> 15000 | F7: Loyer mensuel initial estimé | H7: ='Synthèse Client - détaillée'!J7 -> 750 | I7: ='Synthèse Client - détaillée'!M6 -> Loyer intermédiaire
A11: 🔹 HORIZON 9 ANS - COMPTE EN T
A12: Moyennes mensuelles calculées sur 9 ans (108 mois)
A13: CE QUI RENTRE (+) | F13: CE QUI SORT (−) | K13: BILAN À 9 ANS
A14: Loyer mensuel moyen | D14: =AVERAGE(Moteur!B4:B12)/12 -> 796.61097 | F14: Mensualité de crédit | I14: ='Hypothèses'!B20+'Hypothèses'!B19 -> 1312.3562 | K14: Capital consitué (net PV) | M14: =Moteur!AH12 -> 73286.154
A15: Gain Fiscal à réinvestir / mois | D15: =SUM(Moteur!AG4:AG12)/(9*12) -> 294.11968 | F15: Charges d'exploitation / mois | I15: =AVERAGE(Moteur!C4:C12)/12 -> 238.98329 | K15: Gain fiscal total | M15: =SUM(Moteur!AG4:AG12) -> 31764.926
A16: TOTAL ENTRÉES | D16: =D14+D15 -> 1090.7307 | F16: TOTAL SORTIES | I16: =I14+I15 -> 1551.3395 | K16: dont déficit naturel (intérêts) | M16: =M15-M17 -> 7528.654
A17: EFFORT D'INVESTISSEMENT MENSUEL MOYEN | G17: =D16-I16 -> -460.60881 | K17: dont Jeanbrun (amortissement) | M17: =SUM(Moteur!B125:J125) -> 24236.272
A19: 🔸 HORIZON 15 ANS - COMPTE EN T
A20: Moyennes mensuelles calculées sur 15 ans (180 mois)
A21: CE QUI RENTRE (+) | F21: CE QUI SORT (−) | K21: BILAN À 15 ANS
A22: Loyer mensuel moyen | D22: =AVERAGE(Moteur!B4:B18)/12 -> 834.10689 | F22: Mensualité de crédit | I22: ='Hypothèses'!B20+'Hypothèses'!B19 -> 1312.3562 | K22: Capital consitué (net PV) | M22: =Moteur!AH18 -> 122412.87
A23: Gain Fiscal à réinvestir / mois | D23: =SUM(Moteur!AG4:AG18)/(15*12) -> 260.14178 | F23: Charges d'exploitation / mois | I23: =AVERAGE(Moteur!C4:C18)/12 -> 250.23207 | K23: Gain fiscal total | M23: =SUM(Moteur!AG4:AG18) -> 46825.52
A24: TOTAL ENTRÉES | D24: =D22+D23 -> 1094.2487 | F24: TOTAL SORTIES | I24: =I22+I23 -> 1562.5882 | K24: dont déficit naturel (intérêts) | M24: =M23-M25 -> 3636.2605
A25: EFFORT D'INVESTISSEMENT MENSUEL MOYEN | G25: =D24-I24 -> -468.33957 | K25: dont Jeanbrun (amortissement) | M25: =SUM(Moteur!B125:P125) -> 43189.26
A27: ⭐ HORIZON 25 ANS - COMPTE EN T
A28: Moyennes mensuelles calculées sur 25 ans (300 mois)
A29: CE QUI RENTRE (+) | F29: CE QUI SORT (−) | K29: BILAN À 25 ANS
A30: Loyer mensuel moyen | D30: =AVERAGE(Moteur!B4:B28)/12 -> 901.89071 | F30: Mensualité de crédit | I30: ='Hypothèses'!B20+'Hypothèses'!B19 -> 1312.3562 | K30: Capital consitué (net PV) | M30: =Moteur!AH28 -> 250441.1
A31: Gain Fiscal à réinvestir / mois | D31: =SUM(Moteur!AG4:AG28)/(25*12) -> 185.12192 | F31: Charges d'exploitation / mois | I31: =AVERAGE(Moteur!C4:C28)/12 -> 270.56721 | K31: Gain fiscal total | M31: =SUM(Moteur!AG4:AG28) -> 55536.575
A32: TOTAL ENTRÉES | D32: =D30+D31 -> 1087.0126 | F32: TOTAL SORTIES | I32: =I30+I31 -> 1582.9234 | K32: dont déficit naturel (intérêts) | M32: =M31-M33 -> -20529.165
A33: EFFORT D'INVESTISSEMENT MENSUEL MOYEN | G33: =D32-I32 -> -495.91076 | K33: dont Jeanbrun (amortissement) | M33: =SUM(Moteur!B125:Z125) -> 76065.74
A36: COMMENT LIRE CE TABLEAU
A37: ▸ Le côté VERT (+) = ce que vous percevez : loyers + économie d'impôt grâce au dispositif Jeanbrun.
A38: ▸ Le côté ROUGE (−) = ce que vous déboursez : mensualité de crédit + charges d'exploitation.
A39: ▸ L'EFFORT D'ÉPARGNE = reste à charge réel. Un chiffre négatif = complément mensuel à prévoir.
A40: ▸ Le « Gain fiscal total » se décompose en deux parties qui s'additionnent :
A41: – « dont déficit naturel » : l'économie liée aux intérêts d'emprunt, acquise même sans le Jeanbrun.
A42: – « dont Jeanbrun » : l'économie supplémentaire apportée par l'amortissement du dispositif.
A43: ▸ Ce document est une simulation non contractuelle. Hypothèses d'indexation et fiscalité constantes.
A45: médicis IMMOBILIER NEUF — www.medicis-immobilier-neuf.fr
A46: Ce document est une simulation personnalisée et non contractuelle.
A92: Données graphiques (masqué)
A93: Année | B93: 1 | C93: 2 | D93: 3 | E93: 4 | F93: 5 | G93: 6 | H93: 7 | I93: 8 | J93: 9 | K93: 10 | L93: 11 | M93: 12 | N93: 13 | O93: 14 | P93: 15 | Q93: 16 | R93: 17 | S93: 18 | T93: 19 | U93: 20 | V93: 21 | W93: 22 | X93: 23 | Y93: 24 | Z93: 25
A94: Enrichissement 0% | B94: =Moteur!B102 -> 13820.615 | C94: =Moteur!C102 -> 20663.045 | D94: =Moteur!D102 -> 26887.643 | E94: =Moteur!E102 -> 31560.888 | F94: =Moteur!F102 -> 36478.998 | G94: =Moteur!G102 -> 50403.338 | H94: =Moteur!H102 -> 58471.426 | I94: =Moteur!I102 -> 66809.825 | ... Z94: =Moteur!Z102 -> 250441.1
...

Sheet Synthèse Client - détaillée
A1: PROJECTION FINANCIÈRE — DISPOSITIF JEANBRUN
A2: Simulation personnalisée • Document non contractuel
A4: SITUATION DU FOYER | H4: OPÉRATION IMMOBILIÈRE
A5: Revenus déclarés (avant abatt.) | C5: ='Hypothèses'!B37 -> 95000 | D5: Nombre de parts | F5: ='Hypothèses'!B39 -> 2.5 | H5: Prix d'acquisition | J5: ='Hypothèses'!B4 -> 260000 | K5: Zone | M5: ='Hypothèses'!B9 -> A
A6: Impôt avant opération | C6: =Moteur!P4 -> 12458.98 | D6: TMI | F6: =Moteur!L4 -> 0.3 | H6: Surface pondérée | J6: ='Hypothèses'!F9 -> 47.5 | K6: Type de loyer | M6: ='Hypothèses'!B23 -> Loyer intermédiaire
A7: Impôt après opération (an 1) | C7: =Moteur!AF4 -> 7366.6823 | D7: Économie fiscale an 1 | F7: =Moteur!AG4 -> 5092.2977 | H7: Loyer mensuel initial | J7: ='Hypothèses'!B25 -> 750
A9: FINANCEMENT | H9: DISPOSITIF JEANBRUN
A10: Apport personnel | C10: ='Hypothèses'!B14 -> 15000 | H10: Base amortissable (80%) | J10: ='Hypothèses'!B31 -> 208000
A11: Montant emprunté | C11: ='Hypothèses'!B15 -> 252800 | H11: Amortissement annuel | J11: ='Hypothèses'!B34 -> 7280
A12: Taux nominal | C12: ='Hypothèses'!B16 -> 0.033 | D12: Mensualité totale | F12: ='Tableau dAMT financier'!F8 -> 1312.3562 | H12: Plafond annuel | J12: ='Hypothèses'!B33 -> 8000 | K12: Charges exploitation | M12: ='Hypothèses'!B28 -> 0.3
A14: PROJECTION ANNUELLE
A15: Année | B15: Loyers perçus | C15: Rembours. prêt | D15: Charges exploit. | E15: Amort. Jeanbrun | F15: Revenu foncier net imputé | G15: Impôt avant | H15: Impôt après | I15: Économie fiscale | J15: Effort d'investissement mensuel | K15: Capital net constitué net (0%) | L15: Capital net constitué. net (1,5%) | M15: Amt restant
A16: =Moteur!A4 -> 1 | B16: =Moteur!B4 -> 9000 | C16: ='Tableau dAMT financier'!G16 -> 15748.274 | D16: =Moteur!C4 -> 2700 | E16: =Moteur!F4 -> 7280 | F16: =Moteur!T4 -> -9107.659 | G16: =Moteur!P4 -> 12458.98 | H16: =Moteur!AF4 -> 7366.6823 | I16: =Moteur!AG4 -> 5092.2977 | J16: =Moteur!AI4 -> -362.99803 | K16: =Moteur!B102 -> 13820.615 | L16: =Moteur!B107 -> 17720.615 | M16: ='Hypothèses'!$B$31-Moteur!AL4 -> 200720
A17: =Moteur!A5 -> 2 | B17: =Moteur!B5 -> 9135 | C17: ='Tableau dAMT financier'!G17 -> 15748.274 | D17: =Moteur!C5 -> 2740.5 | E17: =Moteur!F5 -> 7280 | F17: =Moteur!T5 -> -4791.3437 | G17: =Moteur!P5 -> 12356.98 | H17: =Moteur!AF5 -> 8661.5769 | I17: =Moteur!AG5 -> 3695.4031 | J17: =Moteur!AI5 -> -471.53091 | K17: =Moteur!C102 -> 20663.045 | L17: =Moteur!C107 -> 27465.048 | M17: ='Hypothèses'!$B$31-Moteur!AL5 -> 193440
A18: =Moteur!A6 -> 3 | B18: =Moteur!B6 -> 9272.025 | C18: ='Tableau dAMT financier'!G18 -> 15748.274 | D18: =Moteur!C6 -> 2781.6075 | E18: =Moteur!F6 -> 7280 | F18: =Moteur!T6 -> -4466.1793 | G18: =Moteur!P6 -> 12356.98 | H18: =Moteur!AF6 -> 8759.1262 | I18: =Moteur!AG6 -> 3597.8538 | J18: =Moteur!AI6 -> -471.6669 | K18: =Moteur!D102 -> 26887.643 | L18: =Moteur!D107 -> 34464.772 | M18: ='Hypothèses'!$B$31-Moteur!AL6 -> 186160
A19: =Moteur!A7 -> 4 | B19: =Moteur!B7 -> 9411.1054 | C19: ='Tableau dAMT financier'!G19 -> 15748.274 | D19: =Moteur!C7 -> 2823.3316 | E19: =Moteur!F7 -> 7280 | F19: =Moteur!T7 -> -4131.8955 | G19: =Moteur!P7 -> 12356.98 | H19: =Moteur!AF7 -> 8859.4114 | I19: =Moteur!AG7 -> 3497.5686 | J19: =Moteur!AI7 -> -471.91097 | K19: =Moteur!E102 -> 31560.888 | L19: =Moteur!E107 -> 41739.873 | M19: ='Hypothèses'!$B$31-Moteur!AL7 -> 178880
A20: =Moteur!A8 -> 5 | B20: =Moteur!B8 -> 9552.272 | C20: ='Tableau dAMT financier'!G20 -> 15748.274 | D20: =Moteur!C8 -> 2865.6816 | E20: =Moteur!F8 -> 7280 | F20: =Moteur!T8 -> -3788.2134 | G20: =Moteur!P8 -> 12356.98 | H20: =Moteur!AF8 -> 8962.516 | I20: =Moteur!AG8 -> 3394.464 | J20: =Moteur!AI8 -> -472.26831 | K20: =Moteur!F102 -> 36478.998 | L20: =Moteur!F107 -> 49298.868 | M20: ='Hypothèses'!$B$31-Moteur!AL8 -> 171600
A21: =Moteur!A9 -> 6 | B21: =Moteur!B9 -> 9695.556 | C21: ='Tableau dAMT financier'!G21 -> 15748.274 | D21: =Moteur!C9 -> 2908.6668 | E21: =Moteur!F9 -> 7280 | F21: =Moteur!T9 -> -3434.8451 | G21: =Moteur!P9 -> 12356.98 | H21: =Moteur!AF9 -> 9068.5265 | I21: =Moteur!AG9 -> 3288.4535 | J21: =Moteur!AI9 -> -472.74428 | K21: =Moteur!G102 -> 50403.338 | L21: =Moteur!G107 -> 71403.455 | M21: ='Hypothèses'!$B$31-Moteur!AL9 -> 164320
A22: =Moteur!A10 -> 7 | B22: =Moteur!B10 -> 9840.9894 | C22: ='Tableau dAMT financier'!G22 -> 15748.274 | D22: =Moteur!C10 -> 2952.2968 | E22: =Moteur!F10 -> 7280 | F22: =Moteur!T10 -> -3071.4935 | G22: =Moteur!P10 -> 12356.98 | H22: =Moteur!AF10 -> 9177.5319 | I22: =Moteur!AG10 -> 3179.4481 | J22: =Moteur!AI10 -> -473.34445 | K22: =Moteur!H102 -> 58471.426 | L22: =Moteur!H107 -> 80020.536 | M22: ='Hypothèses'!$B$31-Moteur!AL10 -> 157040
A23: =Moteur!A11 -> 8 | B23: =Moteur!B11 -> 9988.6042 | C23: ='Tableau dAMT financier'!G23 -> 15748.274 | D23: =Moteur!C11 -> 2996.5813 | E23: =Moteur!F11 -> 7280 | F23: =Moteur!T11 -> -2697.8521 | G23: =Moteur!P11 -> 12356.98 | H23: =Moteur!AF11 -> 9289.6244 | I23: =Moteur!AG11 -> 3067.3556 | J23: =Moteur!AI11 -> -474.07462 | K23: =Moteur!I102 -> 66809.825 | L23: =Moteur!I107 -> 89280.21 | M23: ='Hypothèses'!$B$31-Moteur!AL11 -> 149760
A24: =Moteur!A12 -> 9 | B24: =Moteur!B12 -> 10138.433 | C24: ='Tableau dAMT financier'!G24 -> 15748.274 | D24: =Moteur!C12 -> 3041.53 | E24: =Moteur!F12 -> 7280 | F24: =Moteur!T12 -> -2313.6043 | G24: =Moteur!P12 -> 12356.98 | H24: =Moteur!AF12 -> 9404.8987 | I24: =Moteur!AG12 -> 2952.0813 | J24: =Moteur!AI12 -> -474.94079 | K24: =Moteur!J102 -> 73286.154 | L24: =Moteur!J107 -> 99194.933 | M24: ='Hypothèses'!$B$31-Moteur!AL12 -> 142480
A25: =Moteur!A13 -> 10 | B25: =Moteur!B13 -> 10290.51 | C25: ='Tableau dAMT financier'!G25 -> 15748.274 | D25: =Moteur!C13 -> 3087.1529 | E25: =Moteur!F13 -> 7280 | F25: =Moteur!T13 -> -1918.4235 | G25: =Moteur!P13 -> 12356.98 | H25: =Moteur!AF13 -> 9523.453 | I25: =Moteur!AG13 -> 2833.527 | J25: =Moteur!AI13 -> -475.94918 | K25: =Moteur!K102 -> 80175.502 | L25: =Moteur!K107 -> 109777.53 | M25: ='Hypothèses'!$B$31-Moteur!AL13 -> 135200
A26: =Moteur!A14 -> 11 | B26: =Moteur!B14 -> 10444.867 | C26: ='Tableau dAMT financier'!G26 -> 15748.274 | D26: =Moteur!C14 -> 3133.4602 | E26: =Moteur!F14 -> 7280 | F26: =Moteur!T14 -> -1511.9724 | G26: =Moteur!P14 -> 12356.98 | H26: =Moteur!AF14 -> 9645.3883 | I26: =Moteur!AG14 -> 2711.5917 | J26: =Moteur!AI14 -> -477.10626 | K26: =Moteur!L102 -> 87570.556 | L26: =Moteur!L107 -> 121041.2 | M26: ='Hypothèses'!$B$31-Moteur!AL14 -> 127920
A27: =Moteur!A15 -> 12 | B27: =Moteur!B15 -> 10601.54 | C27: ='Tableau dAMT financier'!G27 -> 15748.274 | D27: =Moteur!C15 -> 3180.4621 | E27: =Moteur!F15 -> 7280 | F27: =Moteur!T15 -> -1093.903 | G27: =Moteur!P15 -> 12356.98 | H27: =Moteur!AF15 -> 9770.8091 | I27: =Moteur!AG15 -> 2586.1709 | J27: =Moteur!AI15 -> -478.41874 | K27: =Moteur!M102 -> 95481.313 | L27: =Moteur!M107 -> 132999.54 | M27: ='Hypothèses'!$B$31-Moteur!AL15 -> 120640
A28: =Moteur!A16 -> 13 | B28: =Moteur!B16 -> 10760.564 | C28: ='Tableau dAMT financier'!G28 -> 15748.274 | D28: =Moteur!C16 -> 3228.1691 | E28: =Moteur!F16 -> 7280 | F28: =Moteur!T16 -> -663.85601 | G28: =Moteur!P16 -> 12356.98 | H28: =Moteur!AF16 -> 9899.8232 | I28: =Moteur!AG16 -> 2457.1568 | J28: =Moteur!AI16 -> -479.89357 | K28: =Moteur!N102 -> 103918.11 | L28: =Moteur!N107 -> 145666.55 | M28: ='Hypothèses'!$B$31-Moteur!AL16 -> 113360
A29: =Moteur!A17 -> 14 | B29: =Moteur!B17 -> 10921.972 | C29: ='Tableau dAMT financier'!G29 -> 15748.274 | D29: =Moteur!C17 -> 3276.5916 | E29: =Moteur!F17 -> 7280 | F29: =Moteur!T17 -> -221.46064 | G29: =Moteur!P17 -> 12356.98 | H29: =Moteur!AF17 -> 10032.542 | I29: =Moteur!AG17 -> 2324.4382 | J29: =Moteur!AI17 -> -481.53796 | K29: =Moteur!O102 -> 112891.61 | L29: =Moteur!O107 -> 159056.64 | M29: ='Hypothèses'!$B$31-Moteur!AL17 -> 106080
A30: =Moteur!A18 -> 15 | B30: =Moteur!B18 -> 11085.802 | C30: ='Tableau dAMT financier'!G30 -> 15748.274 | D30: =Moteur!C18 -> 3325.7405 | E30: =Moteur!F18 -> 7280 | F30: =Moteur!T18 -> 233.66597 | G30: =Moteur!P18 -> 12356.98 | H30: =Moteur!AF18 -> 10209.27 | I30: =Moteur!AG18 -> 2147.7097 | J30: =Moteur!AI18 -> -486.70861 | K30: =Moteur!P102 -> 122412.87 | L30: =Moteur!P107 -> 173184.66 | M30: ='Hypothèses'!$B$31-Moteur!AL18 -> 98800
A31: =Moteur!A19 -> 16 | B31: =Moteur!B19 -> 11252.089 | C31: ='Tableau dAMT financier'!G31 -> 15748.274 | D31: =Moteur!C19 -> 3375.6266 | E31: =Moteur!F19 -> 7280 | F31: =Moteur!T19 -> 701.91899 | G31: =Moteur!P19 -> 12356.98 | H31: =Moteur!AF19 -> 10425.519 | I31: =Moteur!AG19 -> 1931.461 | J31: =Moteur!AI19 -> -495.02925 | K31: =Moteur!Q102 -> 132493.29 | L31: =Moteur!Q107 -> 188065.89 | M31: ='Hypothèses'!$B$31-Moteur!AL19 -> 91520
A32: =Moteur!A20 -> 17 | B32: =Moteur!B20 -> 11420.87 | C32: ='Tableau dAMT financier'!G32 -> 15748.274 | D32: =Moteur!C20 -> 3426.261 | E32: =Moteur!F20 -> 7280 | F32: =Moteur!T20 -> 1183.7064 | G32: =Moteur!P20 -> 12356.98 | H32: =Moteur!AF20 -> 10643.37 | I32: =Moteur!AG20 -> 1713.6097 | J32: =Moteur!AI20 -> -503.33795 | K32: =Moteur!R102 -> 143144.65 | L32: =Moteur!R107 -> 203716.07 | M32: ='Hypothèses'!$B$31-Moteur!AL20 -> 84240
A33: =Moteur!A21 -> 18 | B33: =Moteur!B21 -> 11592.183 | C33: ='Tableau dAMT financier'!G33 -> 15748.274 | D33: =Moteur!C21 -> 3477.6549 | E33: =Moteur!F21 -> 7280 | F33: =Moteur!T21 -> 1679.4493 | G33: =Moteur!P21 -> 12356.98 | H33: =Moteur!AF21 -> 10867.532 | I33: =Moteur!AG21 -> 1489.4475 | J33: =Moteur!AI21 -> -512.02487 | K33: =Moteur!S102 -> 154379.14 | L33: =Moteur!S107 -> 220151.41 | M33: ='Hypothèses'!$B$31-Moteur!AL21 -> 76960
A34: =Moteur!A22 -> 19 | B34: =Moteur!B22 -> 11766.066 | C34: ='Tableau dAMT financier'!G34 -> 15748.274 | D34: =Moteur!C22 -> 3529.8197 | E34: =Moteur!F22 -> 7280 | F34: =Moteur!T22 -> 2189.5825 | G34: =Moteur!P22 -> 12356.98 | H34: =Moteur!AF22 -> 11098.202 | I34: =Moteur!AG22 -> 1258.7778 | J34: =Moteur!AI22 -> -521.10419 | K34: =Moteur!T102 -> 166209.36 | L34: =Moteur!T107 -> 237388.6 | M34: ='Hypothèses'!$B$31-Moteur!AL22 -> 69680
A35: =Moteur!A23 -> 20 | B35: =Moteur!B23 -> 11942.557 | C35: ='Tableau dAMT financier'!G35 -> 15748.274 | D35: =Moteur!C23 -> 3582.767 | E35: =Moteur!F23 -> 7280 | F35: =Moteur!T23 -> 2714.5548 | G35: =Moteur!P23 -> 12356.98 | H35: =Moteur!AF23 -> 11335.582 | I35: =Moteur!AG23 -> 1021.3976 | J35: =Moteur!AI23 -> -530.59056 | K35: =Moteur!U102 -> 178648.3 | L35: =Moteur!U107 -> 255444.85 | M35: ='Hypothèses'!$B$31-Moteur!AL23 -> 62400
A36: =Moteur!A24 -> 21 | B36: =Moteur!B24 -> 12121.695 | C36: ='Tableau dAMT financier'!G36 -> 15748.274 | D36: =Moteur!C24 -> 3636.5085 | E36: =Moteur!F24 -> 7280 | F36: =Moteur!T24 -> 3254.8296 | G36: =Moteur!P24 -> 12356.98 | H36: =Moteur!AF24 -> 11579.883 | I36: =Moteur!AG24 -> 777.09733 | J36: =Moteur!AI24 -> -540.49918 | K36: =Moteur!V102 -> 191709.43 | L36: =Moteur!V107 -> 274337.85 | M36: ='Hypothèses'!$B$31-Moteur!AL24 -> 55120
A37: =Moteur!A25 -> 22 | B37: =Moteur!B25 -> 12303.52 | C37: ='Tableau dAMT financier'!G37 -> 15748.274 | D37: =Moteur!C25 -> 3691.0561 | E37: =Moteur!F25 -> 7280 | F37: =Moteur!T25 -> 3810.8854 | G37: =Moteur!P25 -> 12356.98 | H37: =Moteur!AF25 -> 11831.319 | I37: =Moteur!AG25 -> 525.66063 | J37: =Moteur!AI25 -> -550.84576 | K37: =Moteur!W102 -> 205011.59 | L37: =Moteur!W107 -> 293299.22 | M37: ='Hypothèses'!$B$31-Moteur!AL25 -> 47840
A38: =Moteur!A26 -> 23 | B38: =Moteur!B26 -> 12488.073 | C38: ='Tableau dAMT financier'!G38 -> 15748.274 | D38: =Moteur!C26 -> 3746.422 | E38: =Moteur!F26 -> 7280 | F38: =Moteur!T26 -> 4383.2159 | G38: =Moteur!P26 -> 12356.98 | H38: =Moteur!AF26 -> 12090.116 | I38: =Moteur!AG26 -> 266.86414 | J38: =Moteur!AI26 -> -561.64655 | K38: =Moteur!X102 -> 219466.27 | L38: =Moteur!X107 -> 314138.87 | M38: ='Hypothèses'!$B$31-Moteur!AL26 -> 40560
A39: =Moteur!A27 -> 24 | B39: =Moteur!B27 -> 12675.394 | C39: ='Tableau dAMT financier'!G39 -> 15748.274 | D39: =Moteur!C27 -> 3802.6183 | E39: =Moteur!F27 -> 7280 | F39: =Moteur!T27 -> 4972.3313 | G39: =Moteur!P27 -> 12356.98 | H39: =Moteur!AF27 -> 12356.503 | I39: =Moteur!AG27 -> 0.47724157 | J39: =Moteur!AI27 -> -572.9184 | K39: =Moteur!Y102 -> 234604.32 | L39: =Moteur!Y107 -> 335903.08 | M39: ='Hypothèses'!$B$31-Moteur!AL27 -> 33280
A40: =Moteur!A28 -> 25 | B40: =Moteur!B28 -> 12865.525 | C40: ='Tableau dAMT financier'!G40 -> 15748.274 | D40: =Moteur!C28 -> 3859.6576 | E40: =Moteur!F28 -> 7280 | F40: =Moteur!T28 -> 5578.7579 | G40: =Moteur!P28 -> 12356.98 | H40: =Moteur!AF28 -> 12630.718 | I40: =Moteur!AG28 -> -273.73816 | J40: =Moteur!AI28 -> -584.67871 | K40: =Moteur!Z102 -> 250441.1 | L40: =Moteur!Z107 -> 358612.07 | M40: ='Hypothèses'!$B$31-Moteur!AL28 -> 26000
A41: TOTAL | B41: =SUM(B16:B40) -> 270567.21 | C41: =SUM(C16:C40) -> 393706.85 | D41: =SUM(D16:D40) -> 81170.164 | E41: =SUM(E16:E40) -> 182000 | I41: =SUM(I16:I40) -> 55536.575
A43: ━ Ligne dorée = horizon 15 ans • ━ Ligne bleue = fin de crédit (20 ans)
A44: Le TRI mesure la rentabilité annualisée si revente à la date indiquée, après impôt PV. L'effort d'épargne est le reste à charge mensuel réel après loyers et économie fiscale.
...

Sheet Revente
A1: SIMULATION DE REVENTE — DISPOSITIF JEANBRUN
A2: Calcul pédagogique de la plus-value et de votre enrichissement net à la revente
B4: 🔹 REVENTE À 9 ANS | E4: 🔸 REVENTE À 15 ANS | H4: ⭐ REVENTE À 25 ANS
B5: PRIX DE VENTE | E5: PRIX DE VENTE | H5: PRIX DE VENTE
B6: Prix de vente (0% revalo.) | C6: ='Hypothèses'!$B$4 -> 260000 | E6: Prix de vente (0% revalo.) | F6: ='Hypothèses'!$B$4 -> 260000 | H6: Prix de vente (0% revalo.) | I6: ='Hypothèses'!$B$4 -> 260000
B7: Prix de vente (1,5%/an revalo.) | C7: ='Hypothèses'!$B$4*1.015^9 -> 297281.39 | E7: Prix de vente (1,5%/an revalo.) | F7: ='Hypothèses'!$B$4*1.015^15 -> 325060.34 | H7: Prix de vente (1,5%/an revalo.) | I7: ='Hypothèses'!$B$4*1.015^25 -> 377245.79
B9: CALCUL DE LA PLUS-VALUE | E9: CALCUL DE LA PLUS-VALUE | H9: CALCUL DE LA PLUS-VALUE
B10: Prix d'acquisition | C10: ='Hypothèses'!$B$4 -> 260000 | E10: Prix d'acquisition | F10: ='Hypothèses'!$B$4 -> 260000 | H10: Prix d'acquisition | I10: ='Hypothèses'!$B$4 -> 260000
B11: + Forfait frais d'acquisition (7,5%) | C11: =MAX('Hypothèses'!$B$4*'Hypothèses'!$B$5,'Hypothèses'!$B$4*'Hypothèses'!$B$43) -> 19500 | E11: + Forfait frais d'acquisition (7,5%) | F11: =MAX('Hypothèses'!$B$4*'Hypothèses'!$B$5,'Hypothèses'!$B$4*'Hypothèses'!$B$43) -> 19500 | H11: + Forfait frais d'acquisition (7,5%) | I11: =MAX('Hypothèses'!$B$4*'Hypothèses'!$B$5,'Hypothèses'!$B$4*'Hypothèses'!$B$43) -> 19500
B12: + Forfait travaux 15% (si > 5 ans) | C12: ='Hypothèses'!$B$4*'Hypothèses'!$B$44 -> 39000 | E12: + Forfait travaux 15% (si > 5 ans) | F12: ='Hypothèses'!$B$4*'Hypothèses'!$B$44 -> 39000 | H12: + Forfait travaux 15% (si > 5 ans) | I12: ='Hypothèses'!$B$4*'Hypothèses'!$B$44 -> 39000
B13: – Amortissements réintégrés | C13: =Moteur!AL12 -> 65520 | E13: – Amortissements réintégrés | F13: =Moteur!AL18 -> 109200 | H13: – Amortissements réintégrés | I13: =Moteur!AL28 -> 182000
B14: = Prix de revient corrigé | C14: ='Hypothèses'!$B$4+MAX('Hypothèses'!$B$4*'Hypothèses'!$B$5,'Hypothèses'!$B$4*'Hypothèses'!$B$43)+'Hypothèses'!$B$4*'Hypothèses'!$B$44-Moteur!AL12 -> 252980 | E14: = Prix de revient corrigé | F14: ='Hypothèses'!$B$4+MAX('Hypothèses'!$B$4*'Hypothèses'!$B$5,'Hypothèses'!$B$4*'Hypothèses'!$B$43)+'Hypothèses'!$B$4*'Hypothèses'!$B$44-Moteur!AL18 -> 209300 | H14: = Prix de revient corrigé | I14: ='Hypothèses'!$B$4+MAX('Hypothèses'!$B$4*'Hypothèses'!$B$5,'Hypothèses'!$B$4*'Hypothèses'!$B$43)+'Hypothèses'!$B$4*'Hypothèses'!$B$44-Moteur!AL28 -> 136500
B16: ➜ PV brute (prix vente 0% – prix revient) | C16: =Moteur!J98 -> 7020 | E16: ➜ PV brute (prix vente 0% – prix revient) | F16: =Moteur!P98 -> 50700 | H16: ➜ PV brute (prix vente 0% – prix revient) | I16: =Moteur!Z98 -> 123500
B17: ➜ PV brute (prix vente 1,5%/an – prix revient) | C17: =Moteur!J103 -> 44301.394 | E17: ➜ PV brute (prix vente 1,5%/an – prix revient) | F17: =Moteur!P103 -> 115760.34 | H17: ➜ PV brute (prix vente 1,5%/an – prix revient) | I17: =Moteur!Z103 -> 240745.79
B19: ABATTEMENTS POUR DURÉE DE DÉTENTION | E19: ABATTEMENTS POUR DURÉE DE DÉTENTION | H19: ABATTEMENTS POUR DURÉE DE DÉTENTION
B20: Abattement IR (%) | C20: =Moteur!AO12 -> 0.24 | E20: Abattement IR (%) | F20: =Moteur!AO18 -> 0.6 | H20: Abattement IR (%) | I20: =Moteur!AO28 -> 1
B21: PV imposable IR (0%) | C21: =Moteur!J99 -> 5335.2 | E21: PV imposable IR (0%) | F21: =Moteur!P99 -> 20280 | H21: PV imposable IR (0%) | I21: =Moteur!Z99 -> 0
B22: PV imposable IR (1,5%) | C22: =Moteur!J104 -> 33669.059 | E22: PV imposable IR (1,5%) | F22: =Moteur!P104 -> 46304.135 | H22: PV imposable IR (1,5%) | I22: =Moteur!Z104 -> 0
B23: Abattement PS (%) | C23: =Moteur!AQ12 -> 0.066 | E23: Abattement PS (%) | F23: =Moteur!AQ18 -> 0.165 | H23: Abattement PS (%) | I23: =Moteur!AQ28 -> 0.55
B24: PV imposable PS (0%) | C24: =Moteur!J100 -> 6556.68 | E24: PV imposable PS (0%) | F24: =Moteur!P100 -> 42334.5 | H24: PV imposable PS (0%) | I24: =Moteur!Z100 -> 55575
B25: PV imposable PS (1,5%) | C25: =Moteur!J105 -> 41377.502 | E25: PV imposable PS (1,5%) | F25: =Moteur!P105 -> 96659.882 | H25: PV imposable PS (1,5%) | I25: =Moteur!Z105 -> 108335.61
B27: IMPÔT SUR LA PLUS-VALUE | E27: IMPÔT SUR LA PLUS-VALUE | H27: IMPÔT SUR LA PLUS-VALUE
B28: IR (19%) — scénario 0% | C28: =Moteur!J99*'Hypothèses'!$B$45 -> 1013.688 | E28: IR (19%) — scénario 0% | F28: =Moteur!P99*'Hypothèses'!$B$45 -> 3853.2 | H28: IR (19%) — scénario 0% | I28: =Moteur!Z99*'Hypothèses'!$B$45 -> 0
B29: IR (19%) — scénario 1,5% | C29: =Moteur!J104*'Hypothèses'!$B$45 -> 6397.1212 | E29: IR (19%) — scénario 1,5% | F29: =Moteur!P104*'Hypothèses'!$B$45 -> 8797.7856 | H29: IR (19%) — scénario 1,5% | I29: =Moteur!Z104*'Hypothèses'!$B$45 -> 0
B30: PS (17,2%) — scénario 0% | C30: =Moteur!J100*'Hypothèses'!$B$46 -> 1127.749 | E30: PS (17,2%) — scénario 0% | F30: =Moteur!P100*'Hypothèses'!$B$46 -> 7281.534 | H30: PS (17,2%) — scénario 0% | I30: =Moteur!Z100*'Hypothèses'!$B$46 -> 9558.9
B31: PS (17,2%) — scénario 1,5% | C31: =Moteur!J105*'Hypothèses'!$B$46 -> 7116.9303 | E31: PS (17,2%) — scénario 1,5% | F31: =Moteur!P105*'Hypothèses'!$B$46 -> 16625.5 | H31: PS (17,2%) — scénario 1,5% | I31: =Moteur!Z105*'Hypothèses'!$B$46 -> 18633.724
B32: Surtaxe éventuelle (0%) | C32: =IF(Moteur!J99<=50000,0,IF(Moteur!J99<=60000,Moteur!J99*0.02-(60000-Moteur!J99)/20,IF(Moteur!J99<=100000,Moteur!J99*0.02,IF(Moteur!J99<=110000,Moteur!J99*0.03-(110000-Moteur!J99)/10,IF(Moteur!J99<=150000,Moteur!J99*0.03,IF(Moteur!J99<=160000,Moteur!J99*0.04-(160000-Moteur!J99)*3/20,IF(Moteur!J99<=200000,Moteur!J99*0.04,IF(Moteur!J99<=210000,Moteur!J99*0.05-(210000-Moteur!J99)/5,IF(Moteur!J99<=250000,Moteur!J99*0.05,IF(Moteur!J99<=260000,Moteur!J99*0.06-(260000-Moteur!J99)/4,Moteur!J99*0.06)))))))))) -> 0 | E32: Surtaxe éventuelle (0%) | F32: =IF(Moteur!P99<=50000,0,IF(Moteur!P99<=60000,Moteur!P99*0.02-(60000-Moteur!P99)/20,IF(Moteur!P99<=100000,Moteur!P99*0.02,IF(Moteur!P99<=110000,Moteur!P99*0.03-(110000-Moteur!P99)/10,IF(Moteur!P99<=150000,Moteur!P99*0.03,IF(Moteur!P99<=160000,Moteur!P99*0.04-(160000-Moteur!P99)*3/20,IF(Moteur!P99<=200000,Moteur!P99*0.04,IF(Moteur!P99<=210000,Moteur!P99*0.05-(210000-Moteur!P99)/5,IF(Moteur!P99<=250000,Moteur!P99*0.05,IF(Moteur!P99<=260000,Moteur!P99*0.06-(260000-Moteur!P99)/4,Moteur!P99*0.06)))))))))) -> 0 | H32: Surtaxe éventuelle (0%) | I32: =IF(Moteur!Z99<=50000,0,IF(Moteur!Z99<=60000,Moteur!Z99*0.02-(60000-Moteur!Z99)/20,IF(Moteur!Z99<=100000,Moteur!Z99*0.02,IF(Moteur!Z99<=110000,Moteur!Z99*0.03-(110000-Moteur!Z99)/10,IF(Moteur!Z99<=150000,Moteur!Z99*0.03,IF(Moteur!Z99<=160000,Moteur!Z99*0.04-(160000-Moteur!Z99)*3/20,IF(Moteur!Z99<=200000,Moteur!Z99*0.04,IF(Moteur!Z99<=210000,Moteur!Z99*0.05-(210000-Moteur!Z99)/5,IF(Moteur!Z99<=250000,Moteur!Z99*0.05,IF(Moteur!Z99<=260000,Moteur!Z99*0.06-(260000-Moteur!Z99)/4,Moteur!Z99*0.06)))))))))) -> 0
B33: Surtaxe éventuelle (1,5%) | C33: =IF(Moteur!J104<=50000,0,IF(Moteur!J104<=60000,Moteur!J104*0.02-(60000-Moteur!J104)/20,IF(Moteur!J104<=100000,Moteur!J104*0.02,IF(Moteur!J104<=110000,Moteur!J104*0.03-(110000-Moteur!J104)/10,IF(Moteur!J104<=150000,Moteur!J104*0.03,IF(Moteur!J104<=160000,Moteur!J104*0.04-(160000-Moteur!J104)*3/20,IF(Moteur!J104<=200000,Moteur!J104*0.04,IF(Moteur!J104<=210000,Moteur!J104*0.05-(210000-Moteur!J104)/5,IF(Moteur!J104<=250000,Moteur!J104*0.05,IF(Moteur!J104<=260000,Moteur!J104*0.06-(260000-Moteur!J104)/4,Moteur!J104*0.06)))))))))) -> 0 | E33: Surtaxe éventuelle (1,5%) | F33: =IF(Moteur!P104<=50000,0,IF(Moteur!P104<=60000,Moteur!P104*0.02-(60000-Moteur!P104)/20,IF(Moteur!P104<=100000,Moteur!P104*0.02,IF(Moteur!P104<=110000,Moteur!P104*0.03-(110000-Moteur!P104)/10,IF(Moteur!P104<=150000,Moteur!P104*0.03,IF(Moteur!P104<=160000,Moteur!P104*0.04-(160000-Moteur!P104)*3/20,IF(Moteur!P104<=200000,Moteur!P104*0.04,IF(Moteur!P104<=210000,Moteur!P104*0.05-(210000-Moteur!P104)/5,IF(Moteur!P104<=250000,Moteur!P104*0.05,IF(Moteur!P104<=260000,Moteur!P104*0.06-(260000-Moteur!P104)/4,Moteur!P104*0.06)))))))))) -> 0 | H33: Surtaxe éventuelle (1,5%) | I33: =IF(Moteur!Z104<=50000,0,IF(Moteur!Z104<=60000,Moteur!Z104*0.02-(60000-Moteur!Z104)/20,IF(Moteur!Z104<=100000,Moteur!Z104*0.02,IF(Moteur!Z104<=110000,Moteur!Z104*0.03-(110000-Moteur!Z104)/10,IF(Moteur!Z104<=150000,Moteur!Z104*0.03,IF(Moteur!Z104<=160000,Moteur!Z104*0.04-(160000-Moteur!Z104)*3/20,IF(Moteur!Z104<=200000,Moteur!Z104*0.04,IF(Moteur!Z104<=210000,Moteur!Z104*0.05-(210000-Moteur!Z104)/5,IF(Moteur!Z104<=250000,Moteur!Z104*0.05,IF(Moteur!Z104<=260000,Moteur!Z104*0.06-(260000-Moteur!Z104)/4,Moteur!Z104*0.06)))))))))) -> 0
B34: = TOTAL IMPÔT PV (0%) | C34: =Moteur!J101 -> 2141.437 | E34: = TOTAL IMPÔT PV (0%) | F34: =Moteur!P101 -> 11134.734 | H34: = TOTAL IMPÔT PV (0%) | I34: =Moteur!Z101 -> 9558.9
B35: = TOTAL IMPÔT PV (1,5%) | C35: =Moteur!J106 -> 13514.052 | E35: = TOTAL IMPÔT PV (1,5%) | F35: =Moteur!P106 -> 25423.285 | H35: = TOTAL IMPÔT PV (1,5%) | I35: =Moteur!Z106 -> 18633.724
B37: CAPITAL RESTANT DÛ | E37: CAPITAL RESTANT DÛ | H37: CAPITAL RESTANT DÛ
B38: CRD à la date de revente | C38: =Moteur!G12 -> 184572.41 | E38: CRD à la date de revente | F38: =Moteur!G18 -> 126452.39 | H38: CRD à la date de revente | I38: =Moteur!G28 -> 2.8521754e-09
B40: CAPITAL CONSTITUÉ NET | E40: CAPITAL CONSTITUÉ NET | H40: CAPITAL CONSTITUÉ NET
B41: = Prix vente – CRD – Impôt PV (0%) | C41: =Moteur!J102 -> 73286.154 | E41: = Prix vente – CRD – Impôt PV (0%) | F41: =Moteur!P102 -> 122412.87 | H41: = Prix vente – CRD – Impôt PV (0%) | I41: =Moteur!Z102 -> 250441.1
B42: = Prix vente – CRD – Impôt PV (1,5%/an) | C42: =Moteur!J107 -> 99194.933 | E42: = Prix vente – CRD – Impôt PV (1,5%/an) | F42: =Moteur!P107 -> 173184.66 | H42: = Prix vente – CRD – Impôt PV (1,5%/an) | I42: =Moteur!Z107 -> 358612.07
A45: 💡 COMPRENDRE VOTRE ENRICHISSEMENT
A46: ▸ Le capital constitué net = ce qui vous reste en poche après avoir soldé votre crédit et payé l'impôt sur la plus-value.
A47: ▸ Plus vous détenez longtemps, plus les abattements pour durée de détention réduisent l'impôt PV : exonération totale d'IR à 22 ans, de PS à 30 ans.
A48: ▸ L'amortissement Jeanbrun est réintégré dans la plus-value à la revente, mais l'économie d'impôt réalisée chaque année (déficit foncier) vous a déjà profité.
A49: ▸ Le scénario 0% est conservateur (pas de hausse des prix). Le scénario 1,5%/an reflète l'évolution historique moyenne du marché immobilier français.
...

Sheet Moteur
A1: SIMULATION
AV2: CSG DÉDUCTIBLE
A3: Année | B3: Loyers annuels | C3: Charges exploit. | D3: Intérêts | E3: Assurance | F3: Amort. Jeanbrun | G3: CRD fin année | H3: Valeur bien | I3: RF autres | J3: Revenu total avant | K3: Quotient avant | L3: TMI avant | M3: Taux moy avant | N3: IR avant | O3: PS avant | P3: Total avant | Q3: RF bruts globaux | R3: Charges financières | S3: Charges non-fin. | T3: RF net global | U3: Déduc. RG | V3: Déf. report. généré | W3: Stock déf. report. | X3: Déf. imputé année N | Y3: RF net taxable | Z3: Revenu total après | AA3: Quotient après | AB3: TMI après | AC3: Taux moy après | AD3: IR après | AE3: PS après | AF3: Total après | AG3: Économie fiscale | AH3: Enrichis. patrimoine net PV | AI3: Effort d'epargne MENSUEL (hors apport) | AJ3: Effort d'épargne moyen | AK3: Cash Flow cumulé (avec apport) | AL3: Amt. cumulé | AM3: Stock report amt | AN3: PV brute si revente | AO3: Abatt. IR PV (%) | AP3: PV impos. IR | AQ3: Abatt. PS PV (%) | AR3: PV impos. PS | AS3: Impôt PV (IR+PS+surtaxe) | AT3: Déf. périmé (>10 ans) | AU3: TRI investisseur (si revente) | AV3: CSG déd. avant (N) | AW3: CSG déd. après (N)
A4: 1 | B4: ='Hypothèses'!$B$26 -> 9000 | C4: =B4*'Hypothèses'!$B$28 -> 2700 | D4: ='Tableau dAMT financier'!E16 -> 8242.859 | E4: ='Tableau dAMT financier'!F16 -> 884.8 | F4: =MIN('Hypothèses'!$B$34,MAX(0,'Hypothèses'!$B$31)) -> 7280 | G4: ='Tableau dAMT financier'!H16 -> 246179.38 | H4: ='Hypothèses'!B4 -> 260000 | I4: ='Hypothèses'!$B$38 -> 5000 | J4: ='Hypothèses'!$B$50+I4 -> 90500 | K4: =J4/'Hypothèses'!$B$39 -> 36200 | L4: =IF(K4<='Barème fiscal'!$B$4,'Barème fiscal'!$C$4,IF(K4<='Barème fiscal'!$B$5,'Barème fiscal'!$C$5,IF(K4<='Barème fiscal'!$B$6,'Barème fiscal'!$C$6,IF(K4<='Barème fiscal'!$B$7,'Barème fiscal'!$C$7,'Barème fiscal'!$C$8)))) -> 0.3 | M4: =IF(J4>0,N4/J4,0) -> 0.12816552 | N4: =MAX(0,IF(J4/2<='Barème fiscal'!$B$4,0,IF(J4/2<='Barème fiscal'!$B$5,J4*'Barème fiscal'!$C$5-'Barème fiscal'!$D$5*2,IF(J4/2<='Barème fiscal'!$B$6,J4*'Barème fiscal'!$C$6-'Barème fiscal'!$D$6*2,IF(J4/2<='Barème fiscal'!$B$7,J4*'Barème fiscal'!$C$7-'Barème fiscal'!$D$7*2,J4*'Barème fiscal'!$C$8-'Barème fiscal'!$D$8*2)))))-MIN(MAX(IF(J4/2<='Barème fiscal'!$B$4,0,IF(J4/2<='Barème fiscal'!$B$5,J4*'Barème fiscal'!$C$5-'Barème fiscal'!$D$5*2,IF(J4/2<='Barème fiscal'!$B$6,J4*'Barème fiscal'!$C$6-'Barème fiscal'!$D$6*2,IF(J4/2<='Barème fiscal'!$B$7,J4*'Barème fiscal'!$C$7-'Barème fiscal'!$D$7*2,J4*'Barème fiscal'!$C$8-'Barème fiscal'!$D$8*2))))-MAX(0,IF(K4<='Barème fiscal'!$B$4,0,IF(K4<='Barème fiscal'!$B$5,J4*'Barème fiscal'!$C$5-'Barème fiscal'!$D$5*'Hypothèses'!$B$39,IF(K4<='Barème fiscal'!$B$6,J4*'Barème fiscal'!$C$6-'Barème fiscal'!$D$6*'Hypothèses'!$B$39,IF(K4<='Barème fiscal'!$B$7,J4*'Barème fiscal'!$C$7-'Barème fiscal'!$D$7*'Hypothèses'!$B$39,J4*'Barème fiscal'!$C$8-'Barème fiscal'!$D$8*'Hypothèses'!$B$39))))),0),MAX('Hypothèses'!$B$39-2,0)*2*'Barème fiscal'!$B$10) -> 11598.98 | O4: =MAX(0,I4)*'Hypothèses'!$B$40 -> 860 | P4: =N4+O4 -> 12458.98 | Q4: =B4+I4 -> 14000 | R4: =D4+E4+'Hypothèses'!$B$21 -> 13127.659 | S4: =C4+F4 -> 9980 | T4: =Q4-R4-S4 -> -9107.659 | U4: =IF(T4>=0,0,IF(Q4>=R4,MAX(T4,-'Barème fiscal'!$B$11),MAX(-S4,-'Barème fiscal'!$B$11))) -> -9107.659 | V4: =IF(T4>=0,0,IF(Q4>=R4,MAX(0,-T4-'Barème fiscal'!$B$11),(R4-Q4)+MAX(0,S4-'Barème fiscal'!$B$11))) -> 0 | W4: =V4 -> 0 | X4: =IF(T4>0,MIN(W4,T4),0) -> 0 | Y4: =MAX(0,T4-X4) -> 0 | Z4: ='Hypothèses'!$B$50+Y4+U4 -> 76392.341 | AA4: =Z4/'Hypothèses'!$B$39 -> 30556.936 | AB4: =IF(AA4<='Barème fiscal'!$B$4,'Barème fiscal'!$C$4,IF(AA4<='Barème fiscal'!$B$5,'Barème fiscal'!$C$5,IF(AA4<='Barème fiscal'!$B$6,'Barème fiscal'!$C$6,IF(AA4<='Barème fiscal'!$B$7,'Barème fiscal'!$C$7,'Barème fiscal'!$C$8)))) -> 0.3 | AC4: =IF(Z4>0,AD4/Z4,0) -> 0.09643221 | AD4: =MAX(0,IF(Z4/2<='Barème fiscal'!$B$4,0,IF(Z4/2<='Barème fiscal'!$B$5,Z4*'Barème fiscal'!$C$5-'Barème fiscal'!$D$5*2,IF(Z4/2<='Barème fiscal'!$B$6,Z4*'Barème fiscal'!$C$6-'Barème fiscal'!$D$6*2,IF(Z4/2<='Barème fiscal'!$B$7,Z4*'Barème fiscal'!$C$7-'Barème fiscal'!$D$7*2,Z4*'Barème fiscal'!$C$8-'Barème fiscal'!$D$8*2)))))-MIN(MAX(IF(Z4/2<='Barème fiscal'!$B$4,0,IF(Z4/2<='Barème fiscal'!$B$5,Z4*'Barème fiscal'!$C$5-'Barème fiscal'!$D$5*2,IF(Z4/2<='Barème fiscal'!$B$6,Z4*'Barème fiscal'!$C$6-'Barème fiscal'!$D$6*2,IF(Z4/2<='Barème fiscal'!$B$7,Z4*'Barème fiscal'!$C$7-'Barème fiscal'!$D$7*2,Z4*'Barème fiscal'!$C$8-'Barème fiscal'!$D$8*2))))-MAX(0,IF(AA4<='Barème fiscal'!$B$4,0,IF(AA4<='Barème fiscal'!$B$5,Z4*'Barème fiscal'!$C$5-'Barème fiscal'!$D$5*'Hypothèses'!$B$39,IF(AA4<='Barème fiscal'!$B$6,Z4*'Barème fiscal'!$C$6-'Barème fiscal'!$D$6*'Hypothèses'!$B$39,IF(AA4<='Barème fiscal'!$B$7,Z4*'Barème fiscal'!$C$7-'Barème fiscal'!$D$7*'Hypothèses'!$B$39,Z4*'Barème fiscal'!$C$8-'Barème fiscal'!$D$8*'Hypothèses'!$B$39))))),0),MAX('Hypothèses'!$B$39-2,0)*2*'Barème fiscal'!$B$10) -> 7366.6823 | AE4: =Y4*'Hypothèses'!$B$40 -> 0 | AF4: =AD4+AE4 -> 7366.6823 | AG4: =P4-AF4 -> 5092.2977 | AH4: =H4-G4-AS4 -> 13820.615 | AI4: =(B4-'Tableau dAMT financier'!G16-C4+AG4)/12 -> -362.99803 | AJ4: =AVERAGE(AI4:AI12) -> -460.60881 | AK4: =-AI4*12-apport -> -10644.024 | AL4: =F4 -> 7280 | AM4: =MAX(0,A4*'Hypothèses'!$B$31*'Hypothèses'!$B$32-AL4) -> 0 | AN4: =H4-('Hypothèses'!$B$4+MAX('Hypothèses'!$B$4*'Hypothèses'!$B$5,'Hypothèses'!$B$4*'Hypothèses'!$B$43)+IF(A4>5,'Hypothèses'!$B$4*'Hypothèses'!$B$44,0)-AL4) -> -12220 | AO4: =IF(A4<=5,0,IF(A4<=21,(A4-5)*0.06,1)) -> 0 | AP4: =MAX(0,AN4*(1-AO4)) -> 0 | AQ4: =IF(A4<=5,0,IF(A4<=21,(A4-5)*0.0165,IF(A4=22,(21-5)*0.0165+0.016,IF(A4<=30,(21-5)*0.0165+0.016+(A4-22)*0.09,1)))) -> 0 | AR4: =MAX(0,AN4*(1-AQ4)) -> 0 | AS4: =IF(AN4<=0,0,AP4*'Hypothèses'!$B$45+AR4*'Hypothèses'!$B$46+IF(AP4<=50000,0,IF(AP4<=60000,AP4*0.02-(60000-AP4)/20,IF(AP4<=100000,AP4*0.02,IF(AP4<=110000,AP4*0.03-(110000-AP4)/10,IF(AP4<=150000,AP4*0.03,IF(AP4<=160000,AP4*0.04-(160000-AP4)*3/20,IF(AP4<=200000,AP4*0.04,IF(AP4<=210000,AP4*0.05-(210000-AP4)/5,IF(AP4<=250000,AP4*0.05,IF(AP4<=260000,AP4*0.06-(260000-AP4)/4,AP4*0.06))))))))))) -> 0 | AT4: 0 | AU4: =IFERROR(IRR(B60:C60),"") -> -0.36902409 | AV4: =MAX(0,I4)*'Barème fiscal'!$B$13 -> 340 | AW4: =Y4*'Barème fiscal'!$B$13 -> 0
A5: 2 | B5: =B4*(1+'Hypothèses'!$B$27) -> 9135 | C5: =B5*'Hypothèses'!$B$28 -> 2740.5 | D5: ='Tableau dAMT financier'!E17 -> 8021.0437 | E5: ='Tableau dAMT financier'!F17 -> 884.8 | F5: =MIN('Hypothèses'!$B$34,MAX(0,'Hypothèses'!$B$31-AL4)) -> 7280 | G5: ='Tableau dAMT financier'!H17 -> 239336.95 | H5: =H4*(1+index) -> 260000 | I5: =I4*(1+index) -> 5000 | J5: ='Hypothèses'!$B$50+I5-AV4 -> 90160 | K5: =J5/'Hypothèses'!$B$39 -> 36064 | L5: =IF(K5<='Barème fiscal'!$B$4,'Barème fiscal'!$C$4,IF(K5<='Barème fiscal'!$B$5,'Barème fiscal'!$C$5,IF(K5<='Barème fiscal'!$B$6,'Barème fiscal'!$C$6,IF(K5<='Barème fiscal'!$B$7,'Barème fiscal'!$C$7,'Barème fiscal'!$C$8)))) -> 0.3 | M5: =IF(J5>0,N5/J5,0) -> 0.12751752 | N5: =MAX(0,IF(J5/2<='Barème fiscal'!$B$4,0,IF(J5/2<='Barème fiscal'!$B$5,J5*'Barème fiscal'!$C$5-'Barème fiscal'!$D$5*2,IF(J5/2<='Barème fiscal'!$B$6,J5*'Barème fiscal'!$C$6-'Barème fiscal'!$D$6*2,IF(J5/2<='Barème fiscal'!$B$7,J5*'Barème fiscal'!$C$7-'Barème fiscal'!$D$7*2,J5*'Barème fiscal'!$C$8-'Barème fiscal'!$D$8*2)))))-MIN(MAX(IF(J5/2<='Barème fiscal'!$B$4,0,IF(J5/2<='Barème fiscal'!$B$5,J5*'Barème fiscal'!$C$5-'Barème fiscal'!$D$5*2,IF(J5/2<='Barème fiscal'!$B$6,J5*'Barème fiscal'!$C$6-'Barème fiscal'!$D$6*2,IF(J5/2<='Barème fiscal'!$B$7,J5*'Barème fiscal'!$C$7-'Barème fiscal'!$D$7*2,J5*'Barème fiscal'!$C$8-'Barème fiscal'!$D$8*2))))-MAX(0,IF(K5<='Barème fiscal'!$B$4,0,IF(K5<='Barème fiscal'!$B$5,J5*'Barème fiscal'!$C$5-'Barème fiscal'!$D$5*'Hypothèses'!$B$39,IF(K5<='Barème fiscal'!$B$6,J5*'Barème fiscal'!$C$6-'Barème fiscal'!$D$6*'Hypothèses'!$B$39,IF(K5<='Barème fiscal'!$B$7,J5*'Barème fiscal'!$C$7-'Barème fiscal'!$D$7*'Hypothèses'!$B$39,J5*'Barème fiscal'!$C$8-'Barème fiscal'!$D$8*'Hypothèses'!$B$39))))),0),MAX('Hypothèses'!$B$39-2,0)*2*'Barème fiscal'!$B$10) -> 11496.98 | O5: =MAX(0,I5)*'Hypothèses'!$B$40 -> 860 | P5: =N5+O5 -> 12356.98 | Q5: =B5+I5 -> 14135 | R5: =D5+E5 -> 8905.8437 | S5: =C5+F5 -> 10020.5 | T5: =Q5-R5-S5 -> -4791.3437 | U5: =IF(T5>=0,0,IF(Q5>=R5,MAX(T5,-'Barème fiscal'!$B$11),MAX(-S5,-'Barème fiscal'!$B$11))) -> -4791.3437 | V5: =IF(T5>=0,0,IF(Q5>=R5,MAX(0,-T5-'Barème fiscal'!$B$11),(R5-Q5)+MAX(0,S5-'Barème fiscal'!$B$11))) -> 0 | W5: =W4+V5-X4-AT5 -> 0 | X5: =IF(T5>0,MIN(W5,T5),0) -> 0 | Y5: =MAX(0,T5-X5) -> 0 | Z5: ='Hypothèses'!$B$50+Y5+U5-AW4 -> 80708.656 | AA5: =Z5/'Hypothèses'!$B$39 -> 32283.463 | AB5: =IF(AA5<='Barème fiscal'!$B$4,'Barème fiscal'!$C$4,IF(AA5<='Barème fiscal'!$B$5,'Barème fiscal'!$C$5,IF(AA5<='Barème fiscal'!$B$6,'Barème fiscal'!$C$6,IF(AA5<='Barème fiscal'!$B$7,'Barème fiscal'!$C$7,'Barème fiscal'!$C$8)))) -> 0.3 | AC5: =IF(Z5>0,AD5/Z5,0) -> 0.10731906 | AD5: =MAX(0,IF(Z5/2<='Barème fiscal'!$B$4,0,IF(Z5/2<='Barème fiscal'!$B$5,Z5*'Barème fiscal'!$C$5-'Barème fiscal'!$D$5*2,IF(Z5/2<='Barème fiscal'!$B$6,Z5*'Barème fiscal'!$C$6-'Barème fiscal'!$D$6*2,IF(Z5/2<='Barème fiscal'!$B$7,Z5*'Barème fiscal'!$C$7-'Barème fiscal'!$D$7*2,Z5*'Barème fiscal'!$C$8-'Barème fiscal'!$D$8*2)))))-MIN(MAX(IF(Z5/2<='Barème fiscal'!$B$4,0,IF(Z5/2<='Barème fiscal'!$B$5,Z5*'Barème fiscal'!$C$5-'Barème fiscal'!$D$5*2,IF(Z5/2<='Barème fiscal'!$B$6,Z5*'Barème fiscal'!$C$6-'Barème fiscal'!$D$6*2,IF(Z5/2<='Barème fiscal'!$B$7,Z5*'Barème fiscal'!$C$7-'Barème fiscal'!$D$7*2,Z5*'Barème fiscal'!$C$8-'Barème fiscal'!$D$8*2))))-MAX(0,IF(AA5<='Barème fiscal'!$B$4,0,IF(AA5<='Barème fiscal'!$B$5,Z5*'Barème fiscal'!$C$5-'Barème fiscal'!$D$5*'Hypothèses'!$B$39,IF(AA5<='Barème fiscal'!$B$6,Z5*'Barème fiscal'!$C$6-'Barème fiscal'!$D$6*'Hypothèses'!$B$39,IF(AA5<='Barème fiscal'!$B$7,Z5*'Barème fiscal'!$C$7-'Barème fiscal'!$D$7*'Hypothèses'!$B$39,Z5*'Barème fiscal'!$C$8-'Barème fiscal'!$D$8*'Hypothèses'!$B$39))))),0),MAX('Hypothèses'!$B$39-2,0)*2*'Barème fiscal'!$B$10) -> 8661.5769 | AE5: =Y5*'Hypothèses'!$B$40 -> 0 | AF5: =AD5+AE5 -> 8661.5769 | AG5: =P5-AF5 -> 3695.4031 | AH5: =H5-G5-AS5 -> 20663.045 | AI5: =(B5-'Tableau dAMT financier'!G17-C5+AG5)/12 -> -471.53091 | AK5: =AK4+AI5*12 -> -16302.395 | AL5: =AL4+F5 -> 14560 | AM5: =MAX(0,A5*'Hypothèses'!$B$31*'Hypothèses'!$B$32-AL5) -> 0 | AN5: =H5-('Hypothèses'!$B$4+MAX('Hypothèses'!$B$4*'Hypothèses'!$B$5,'Hypothèses'!$B$4*'Hypothèses'!$B$43)+IF(A5>5,'Hypothèses'!$B$4*'Hypothèses'!$B$44,0)-AL5) -> -4940 | AO5: =IF(A5<=5,0,IF(A5<=21,(A5-5)*0.06,1)) -> 0 | AP5: =MAX(0,AN5*(1-AO5)) -> 0 | AQ5: =IF(A5<=5,0,IF(A5<=21,(A5-5)*0.0165,IF(A5=22,(21-5)*0.0165+0.016,IF(A5<=30,(21-5)*0.0165+0.016+(A5-22)*0.09,1)))) -> 0 | AR5: =MAX(0,AN5*(1-AQ5)) -> 0 | AS5: =IF(AN5<=0,0,AP5*'Hypothèses'!$B$45+AR5*'Hypothèses'!$B$46+IF(AP5<=50000,0,IF(AP5<=60000,AP5*0.02-(60000-AP5)/20,IF(AP5<=100000,AP5*0.02,IF(AP5<=110000,AP5*0.03-(110000-AP5)/10,IF(AP5<=150000,AP5*0.03,IF(AP5<=160000,AP5*0.04-(160000-AP5)*3/20,IF(AP5<=200000,AP5*0.04,IF(AP5<=210000,AP5*0.05-(210000-AP5)/5,IF(AP5<=250000,AP5*0.05,IF(AP5<=260000,AP5*0.06-(260000-AP5)/4,AP5*0.06))))))))))) -> 0 | AT5: 0 | AU5: =IFERROR(IRR(B61:D61),"") -> -0.1345586 | AV5: =MAX(0,I5)*'Barème fiscal'!$B$13 -> 340 | AW5: =Y5*'Barème fiscal'!$B$13 -> 0
A6: 3 | B6: =B5*(1+'Hypothèses'!$B$27) -> 9272.025 | C6: =B6*'Hypothèses'!$B$28 -> 2781.6075 | D6: ='Tableau dAMT financier'!E18 -> 7791.7968 | E6: ='Tableau dAMT financier'!F18 -> 884.8 | F6: =MIN('Hypothèses'!$B$34,MAX(0,'Hypothèses'!$B$31-AL5)) -> 7280 | G6: ='Tableau dAMT financier'!H18 -> 232265.28 | H6: =H5*(1+index) -> 260000 | I6: =I5*(1+index) -> 5000 | J6: ='Hypothèses'!$B$50+I6-AV5 -> 90160 | K6: =J6/'Hypothèses'!$B$39 -> 36064 | L6: =IF(K6<='Barème fiscal'!$B$4,'Barème fiscal'!$C$4,IF(K6<='Barème fiscal'!$B$5,'Barème fiscal'!$C$5,IF(K6<='Barème fiscal'!$B$6,'Barème fiscal'!$C$6,IF(K6<='Barème fiscal'!$B$7,'Barème fiscal'!$C$7,'Barème fiscal'!$C$8)))) -> 0.3 | M6: =IF(J6>0,N6/J6,0) -> 0.12751752 | N6: =MAX(0,IF(J6/2<='Barème fiscal'!$B$4,0,IF(J6/2<='Barème fiscal'!$B$5,J6*'Barème fiscal'!$C$5-'Barème fiscal'!$D$5*2,IF(J6/2<='Barème fiscal'!$B$6,J6*'Barème fiscal'!$C$6-'Barème fiscal'!$D$6*2,IF(J6/2<='Barème fiscal'!$B$7,J6*'Barème fiscal'!$C$7-'Barème fiscal'!$D$7*2,J6*'Barème fiscal'!$C$8-'Barème fiscal'!$D$8*2)))))-MIN(MAX(IF(J6/2<='Barème fiscal'!$B$4,0,IF(J6/2<='Barème fiscal'!$B$5,J6*'Barème fiscal'!$C$5-'Barème fiscal'!$D$5*2,IF(J6/2<='Barème fiscal'!$B$6,J6*'Barème fiscal'!$C$6-'Barème fiscal'!$D$6*2,IF(J6/2<='Barème fiscal'!$B$7,J6*'Barème fiscal'!$C$7-'Barème fiscal'!$D$7*2,J6*'Barème fiscal'!$C$8-'Barème fiscal'!$D$8*2))))-MAX(0,IF(K6<='Barème fiscal'!$B$4,0,IF(K6<='Barème fiscal'!$B$5,J6*'Barème fiscal'!$C$5-'Barème fiscal'!$D$5*'Hypothèses'!$B$39,IF(K6<='Barème fiscal'!$B$6,J6*'Barème fiscal'!$C$6-'Barème fiscal'!$D$6*'Hypothèses'!$B$39,IF(K6<='Barème fiscal'!$B$7,J6*'Barème fiscal'!$C$7-'Barème fiscal'!$D$7*'Hypothèses'!$B$39,J6*'Barème fiscal'!$C$8-'Barème fiscal'!$D$8*'Hypothèses'!$B$39))))),0),MAX('Hypothèses'!$B$39-2,0)*2*'Barème fiscal'!$B$10) -> 11496.98 | O6: =MAX(0,I6)*'Hypothèses'!$B$40 -> 860 | P6: =N6+O6 -> 12356.98 | Q6: =B6+I6 -> 14272.025 | R6: =D6+E6 -> 8676.5968 | S6: =C6+F6 -> 10061.608 | T6: =Q6-R6-S6 -> -4466.1793 | U6: =IF(T6>=0,0,IF(Q6>=R6,MAX(T6,-'Barème fiscal'!$B$11),MAX(-S6,-'Barème fiscal'!$B$11))) -> -4466.1793 | V6: =IF(T6>=0,0,IF(Q6>=R6,MAX(0,-T6-'Barème fiscal'!$B$11),(R6-Q6)+MAX(0,S6-'Barème fiscal'!$B$11))) -> 0 | W6: =W5+V6-X5-AT6 -> 0 | X6: =IF(T6>0,MIN(W6,T6),0) -> 0 | Y6: =MAX(0,T6-X6) -> 0 | Z6: ='Hypothèses'!$B$50+Y6+U6-AW5 -> 81033.821 | AA6: =Z6/'Hypothèses'!$B$39 -> 32413.528 | AB6: =IF(AA6<='Barème fiscal'!$B$4,'Barème fiscal'!$C$4,IF(AA6<='Barème fiscal'!$B$5,'Barème fiscal'!$C$5,IF(AA6<='Barème fiscal'!$B$6,'Barème fiscal'!$C$6,IF(AA6<='Barème fiscal'!$B$7,'Barème fiscal'!$C$7,'Barème fiscal'!$C$8)))) -> 0.3 | AC6: =IF(Z6>0,AD6/Z6,0) -> 0.10809223 | AD6: =MAX(0,IF(Z6/2<='Barème fiscal'!$B$4,0,IF(Z6/2<='Barème fiscal'!$B$5,Z6*'Barème fiscal'!$C$5-'Barème fiscal'!$D$5*2,IF(Z6/2<='Barème fiscal'!$B$6,Z6*'Barème fiscal'!$C$6-'Barème fiscal'!$D$6*2,IF(Z6/2<='Barème fiscal'!$B$7,Z6*'Barème fiscal'!$C$7-'Barème fiscal'!$D$7*2,Z6*'Barème fiscal'!$C$8-'Barème fiscal'!$D$8*2)))))-MIN(MAX(IF(Z6/2<='Barème fiscal'!$B$4,0,IF(Z6/2<='Barème fiscal'!$B$5,Z6*'Barème fiscal'!$C$5-'Barème fiscal'!$D$5*2,IF(Z6/2<='Barème fiscal'!$B$6,Z6*'Barème fiscal'!$C$6-'Barème fiscal'!$D$6*2,IF(Z6/2<='Barème fiscal'!$B$7,Z6*'Barème fiscal'!$C$7-'Barème fiscal'!$D$7*2,Z6*'Barème fiscal'!$C$8-'Barème fiscal'!$D$8*2))))-MAX(0,IF(AA6<='Barème fiscal'!$B$4,0,IF(AA6<='Barème fiscal'!$B$5,Z6*'Barème fiscal'!$C$5-'Barème fiscal'!$D$5*'Hypothèses'!$B$39,IF(AA6<='Barème fiscal'!$B$6,Z6*'Barème fiscal'!$C$6-'Barème fiscal'!$D$6*'Hypothèses'!$B$39,IF(AA6<='Barème fiscal'!$B$7,Z6*'Barème fiscal'!$C$7-'Barème fiscal'!$D$7*'Hypothèses'!$B$39,Z6*'Barème fiscal'!$C$8-'Barème fiscal'!$D$8*'Hypothèses'!$B$39))))),0),MAX('Hypothèses'!$B$39-2,0)*2*'Barème fiscal'!$B$10) -> 8759.1262 | AE6: =Y6*'Hypothèses'!$B$40 -> 0 | AF6: =AD6+AE6 -> 8759.1262 | AG6: =P6-AF6 -> 3597.8538 | AH6: =H6-G6-AS6 -> 26887.643 | AI6: =(B6-'Tableau dAMT financier'!G18-C6+AG6)/12 -> -471.6669 | AK6: =AK5+AI6*12 -> -21962.397 | AL6: =AL5+F6 -> 21840 | AM6: =MAX(0,A6*'Hypothèses'!$B$31*'Hypothèses'!$B$32-AL6) -> 0 | AN6: =H6-('Hypothèses'!$B$4+MAX('Hypothèses'!$B$4*'Hypothèses'!$B$5,'Hypothèses'!$B$4*'Hypothèses'!$B$43)+IF(A6>5,'Hypothèses'!$B$4*'Hypothèses'!$B$44,0)-AL6) -> 2340 | AO6: =IF(A6<=5,0,IF(A6<=21,(A6-5)*0.06,1)) -> 0 | AP6: =MAX(0,AN6*(1-AO6)) -> 2340 | AQ6: =IF(A6<=5,0,IF(A6<=21,(A6-5)*0.0165,IF(A6=22,(21-5)*0.0165+0.016,IF(A6<=30,(21-5)*0.0165+0.016+(A6-22)*0.09,1)))) -> 0 | AR6: =MAX(0,AN6*(1-AQ6)) -> 2340 | AS6: =IF(AN6<=0,0,AP6*'Hypothèses'!$B$45+AR6*'Hypothèses'!$B$46+IF(AP6<=50000,0,IF(AP6<=60000,AP6*0.02-(60000-AP6)/20,IF(AP6<=100000,AP6*0.02,IF(AP6<=110000,AP6*0.03-(110000-AP6)/10,IF(AP6<=150000,AP6*0.03,IF(AP6<=160000,AP6*0.04-(160000-AP6)*3/20,IF(AP6<=200000,AP6*0.04,IF(AP6<=210000,AP6*0.05-(210000-AP6)/5,IF(AP6<=250000,AP6*0.05,IF(AP6<=260000,AP6*0.06-(260000-AP6)/4,AP6*0.06))))))))))) -> 847.08 | AT6: 0 | AU6: =IFERROR(IRR(B62:E62),"") -> -0.067490088 | AV6: =MAX(0,I6)*'Barème fiscal'!$B$13 -> 340 | AW6: =Y6*'Barème fiscal'!$B$13 -> 0
A7: 4 | B7: =B6*(1+'Hypothèses'!$B$27) -> 9411.1054 | C7: =B7*'Hypothèses'!$B$28 -> 2823.3316 | D7: ='Tableau dAMT financier'!E19 -> 7554.8692 | E7: ='Tableau dAMT financier'!F19 -> 884.8 | F7: =MIN('Hypothèses'!$B$34,MAX(0,'Hypothèses'!$B$31-AL6)) -> 7280 | G7: ='Tableau dAMT financier'!H19 -> 224956.67 | H7: =H6*(1+index) -> 260000 | I7: =I6*(1+index) -> 5000 | J7: ='Hypothèses'!$B$50+I7-AV6 -> 90160 | K7: =J7/'Hypothèses'!$B$39 -> 36064 | L7: =IF(K7<='Barème fiscal'!$B$4,'Barème fiscal'!$C$4,IF(K7<='Barème fiscal'!$B$5,'Barème fiscal'!$C$5,IF(K7<='Barème fiscal'!$B$6,'Barème fiscal'!$C$6,IF(K7<='Barème fiscal'!$B$7,'Barème fiscal'!$C$7,'Barème fiscal'!$C$8)))) -> 0.3 | M7: =IF(J7>0,N7/J7,0) -> 0.12751752 | N7: =MAX(0,IF(J7/2<='Barème fiscal'!$B$4,0,IF(J7/2<='Barème fiscal'!$B$5,J7*'Barème fiscal'!$C$5-'Barème fiscal'!$D$5*2,IF(J7/2<='Barème fiscal'!$B$6,J7*'Barème fiscal'!$C$6-'Barème fiscal'!$D$6*2,IF(J7/2<='Barème fiscal'!$B$7,J7*'Barème fiscal'!$C$7-'Barème fiscal'!$D$7*2,J7*'Barème fiscal'!$C$8-'Barème fiscal'!$D$8*2)))))-MIN(MAX(IF(J7/2<='Barème fiscal'!$B$4,0,IF(J7/2<='Barème fiscal'!$B$5,J7*'Barème fiscal'!$C$5-'Barème fiscal'!$D$5*2,IF(J7/2<='Barème fiscal'!$B$6,J7*'Barème fiscal'!$C$6-'Barème fiscal'!$D$6*2,IF(J7/2<='Barème fiscal'!$B$7,J7*'Barème fiscal'!$C$7-'Barème fiscal'!$D$7*2,J7*'Barème fiscal'!$C$8-'Barème fiscal'!$D$8*2))))-MAX(0,IF(K7<='Barème fiscal'!$B$4,0,IF(K7<='Barème fiscal'!$B$5,J7*'Barème fiscal'!$C$5-'Barème fiscal'!$D$5*'Hypothèses'!$B$39,IF(K7<='Barème fiscal'!$B$6,J7*'Barème fiscal'!$C$6-'Barème fiscal'!$D$6*'Hypothèses'!$B$39,IF(K7<='Barème fiscal'!$B$7,J7*'Barème fiscal'!$C$7-'Barème fiscal'!$D$7*'Hypothèses'!$B$39,J7*'Barème fiscal'!$C$8-'Barème fiscal'!$D$8*'Hypothèses'!$B$39))))),0),MAX('Hypothèses'!$B$39-2,0)*2*'Barème fiscal'!$B$10) -> 11496.98 | O7: =MAX(0,I7)*'Hypothèses'!$B$40 -> 860 | P7: =N7+O7 -> 12356.98 | Q7: =B7+I7 -> 14411.105 | R7: =D7+E7 -> 8439.6692 | S7: =C7+F7 -> 10103.332 | T7: =Q7-R7-S7 -> -4131.8955 | U7: =IF(T7>=0,0,IF(Q7>=R7,MAX(T7,-'Barème fiscal'!$B$11),MAX(-S7,-'Barème fiscal'!$B$11))) -> -4131.8955 | V7: =IF(T7>=0,0,IF(Q7>=R7,MAX(0,-T7-'Barème fiscal'!$B$11),(R7-Q7)+MAX(0,S7-'Barème fiscal'!$B$11))) -> 0 | W7: =W6+V7-X6-AT7 -> 0 | X7: =IF(T7>0,MIN(W7,T7),0) -> 0 | Y7: =MAX(0,T7-X7) -> 0 | Z7: ='Hypothèses'!$B$50+Y7+U7-AW6 -> 81368.105 | AA7: =Z7/'Hypothèses'!$B$39 -> 32547.242 | AB7: =IF(AA7<='Barème fiscal'!$B$4,'Barème fiscal'!$C$4,IF(AA7<='Barème fiscal'!$B$5,'Barème fiscal'!$C$5,IF(AA7<='Barème fiscal'!$B$6,'Barème fiscal'!$C$6,IF(AA7<='Barème fiscal'!$B$7,'Barème fiscal'!$C$7,'Barème fiscal'!$C$8)))) -> 0.3 | AC7: =IF(Z7>0,AD7/Z7,0) -> 0.10888064 | AD7: =MAX(0,IF(Z7/2<='Barème fiscal'!$B$4,0,IF(Z7/2<='Barème fiscal'!$B$5,Z7*'Barème fiscal'!$C$5-'Barème fiscal'!$D$5*2,IF(Z7/2<='Barème fiscal'!$B$6,Z7*'Barème fiscal'!$C$6-'Barème fiscal'!$D$6*2,IF(Z7/2<='Barème fiscal'!$B$7,Z7*'Barème fiscal'!$C$7-'Barème fiscal'!$D$7*2,Z7*'Barème fiscal'!$C$8-'Barème fiscal'!$D$8*2)))))-MIN(MAX(IF(Z7/2<='Barème fiscal'!$B$4,0,IF(Z7/2<='Barème fiscal'!$B$5,Z7*'Barème fiscal'!$C$5-'Barème fiscal'!$D$5*2,IF(Z7/2<='Barème fiscal'!$B$6,Z7*'Barème fiscal'!$C$6-'Barème fiscal'!$D$6*2,IF(Z7/2<='Barème fiscal'!$B$7,Z7*'Barème fiscal'!$C$7-'Barème fiscal'!$D$7*2,Z7*'Barème fiscal'!$C$8-'Barème fiscal'!$D$8*2))))-MAX(0,IF(AA7<='Barème fiscal'!$B$4,0,IF(AA7<='Barème fiscal'!$B$5,Z7*'Barème fiscal'!$C$5-'Barème fiscal'!$D$5*'Hypothèses'!$B$39,IF(AA7<='Barème fiscal'!$B$6,Z7*'Barème fiscal'!$C$6-'Barème fiscal'!$D$6*'Hypothèses'!$B$39,IF(AA7<='Barème fiscal'!$B$7,Z7*'Barème fiscal'!$C$7-'Barème fiscal'!$D$7*'Hypothèses'!$B$39,Z7*'Barème fiscal'!$C$8-'Barème fiscal'!$D$8*'Hypothèses'!$B$39))))),0),MAX('Hypothèses'!$B$39-2,0)*2*'Barème fiscal'!$B$10) -> 8859.4114 | AE7: =Y7*'Hypothèses'!$B$40 -> 0 | AF7: =AD7+AE7 -> 8859.4114 | AG7: =P7-AF7 -> 3497.5686 | AH7: =H7-G7-AS7 -> 31560.888 | AI7: =(B7-'Tableau dAMT financier'!G19-C7+AG7)/12 -> -471.91097 | AK7: =AK6+AI7*12 -> -27625.329 | AL7: =AL6+F7 -> 29120 | AM7: =MAX(0,A7*'Hypothèses'!$B$31*'Hypothèses'!$B$32-AL7) -> 0 | AN7: =H7-('Hypothèses'!$B$4+MAX('Hypothèses'!$B$4*'Hypothèses'!$B$5,'Hypothèses'!$B$4*'Hypothèses'!$B$43)+IF(A7>5,'Hypothèses'!$B$4*'Hypothèses'!$B$44,0)-AL7) -> 9620 | AO7: =IF(A7<=5,0,IF(A7<=21,(A7-5)*0.06,1)) -> 0 | AP7: =MAX(0,AN7*(1-AO7)) -> 9620 | AQ7: =IF(A7<=5,0,IF(A7<=21,(A7-5)*0.0165,IF(A7=22,(21-5)*0.0165+0.016,IF(A7<=30,(21-5)*0.0165+0.016+(A7-22)*0.09,1)))) -> 0 | AR7: =MAX(0,AN7*(1-AQ7)) -> 9620 | AS7: =IF(AN7<=0,0,AP7*'Hypothèses'!$B$45+AR7*'Hypothèses'!$B$46+IF(AP7<=50000,0,IF(AP7<=60000,AP7*0.02-(60000-AP7)/20,IF(AP7<=100000,AP7*0.02,IF(AP7<=110000,AP7*0.03-(110000-AP7)/10,IF(AP7<=150000,AP7*0.03,IF(AP7<=160000,AP7*0.04-(160000-AP7)*3/20,IF(AP7<=200000,AP7*0.04,IF(AP7<=210000,AP7*0.05-(210000-AP7)/5,IF(AP7<=250000,AP7*0.05,IF(AP7<=260000,AP7*0.06-(260000-AP7)/4,AP7*0.06))))))))))) -> 3482.44 | AT7: 0 | AU7: =IFERROR(IRR(B63:F63),"") -> -0.05681273 | AV7: =MAX(0,I7)*'Barème fiscal'!$B$13 -> 340 | AW7: =Y7*'Barème fiscal'!$B$13 -> 0
